Workbook
Name Slicer_hr: #N/A
Name Slicer_mnth: #N/A
Name Slicer_temp_cat: #N/A
Name Slicer_Time_period: #N/A
Name Slicer_weather_category: #N/A
Name Slicer_Week_days: #N/A
Name Slicer_week_type: #N/A

Sheet dataset_1
A1: instant | B1: dteday | C1: season | D1: yr | E1: mnth | F1: hr | G1: holiday | H1: weekday | I1: weathersit | J1: temp
A2: 14 | B2: 40544 | C2: 1 | D2: 0 | E2: 1 | F2: 13 | G2: FALSE | H2: 6 | I2: 2 | J2: 0.46 | K2: 1. Conditional Formatting (Coloring Data)
A3: 15 | B3: 40544 | C3: 1 | D3: 0 | E3: 1 | F3: 14 | G3: FALSE | H3: 6 | I3: 2 | J3: 0.46 | L3: weathersit = 3 → Red color (bad weather)
A4: 24 | B4: 40544 | C4: 1 | D4: 0 | E4: 1 | F4: 23 | G4: FALSE | H4: 6 | I4: 2 | J4: 0.46 | L4: High temp → Red color
A5: 25 | B5: 40545 | C5: 1 | D5: 0 | E5: 1 | F5: 0 | G5: FALSE | H5: 0 | I5: 2 | J5: 0.46 | L5: shoreted by temp higest to lowsest to finding
A6: 28 | B6: 40545 | C6: 1 | D6: 0 | E6: 1 | F6: 3 | G6: FALSE | H6: 0 | I6: 2 | J6: 0.46
A7: 29 | B7: 40545 | C7: 1 | D7: 0 | E7: 1 | F7: 4 | G7: FALSE | H7: 0 | I7: 2 | J7: 0.46
A8: 16 | B8: 40544 | C8: 1 | D8: 0 | E8: 1 | F8: 15 | G8: FALSE | H8: 6 | I8: 2 | J8: 0.44
A9: 18 | B9: 40544 | C9: 1 | D9: 0 | E9: 1 | F9: 17 | G9: FALSE | H9: 6 | I9: 2 | J9: 0.44 | K9: 2. Basic Aggregations on temp
A10: 26 | B10: 40545 | C10: 1 | D10: 0 | E10: 1 | F10: 1 | G10: FALSE | H10: 0 | I10: 2 | J10: 0.44
A11: 13 | B11: 40544 | C11: 1 | D11: 0 | E11: 1 | F11: 12 | G11: FALSE | H11: 6 | I11: 1 | J11: 0.42
A12: 17 | B12: 40544 | C12: 1 | D12: 0 | E12: 1 | F12: 16 | G12: FALSE | H12: 6 | I12: 2 | J12: 0.42 | L12: COUNT | O12: =COUNT(J:J) -> 610
A13: 19 | B13: 40544 | C13: 1 | D13: 0 | E13: 1 | F13: 18 | G13: FALSE | H13: 6 | I13: 3 | J13: 0.42 | L13: COUNTIF( HOLIDAY TRUE) | O13: =COUNTIF(G2:G611, TRUE) -> 24
A14: 20 | B14: 40544 | C14: 1 | D14: 0 | E14: 1 | F14: 19 | G14: FALSE | H14: 6 | I14: 3 | J14: 0.42 | L14: COUNTIF( HOLIDAY FALSE) | O14: =COUNTIF(G3:G612, FALSE) -> 585
A15: 27 | B15: 40545 | C15: 1 | D15: 0 | E15: 1 | F15: 2 | G15: FALSE | H15: 0 | I15: 2 | J15: 0.42
A16: 30 | B16: 40545 | C16: 1 | D16: 0 | E16: 1 | F16: 6 | G16: FALSE | H16: 0 | I16: 3 | J16: 0.42 | K16: 3. TEXT Functions on dteday
A17: 21 | B17: 40544 | C17: 1 | D17: 0 | E17: 1 | F17: 20 | G17: FALSE | H17: 6 | I17: 2 | J17: 0.4
A18: 22 | B18: 40544 | C18: 1 | D18: 0 | E18: 1 | F18: 21 | G18: FALSE | H18: 6 | I18: 2 | J18: 0.4 | L18: Sample dteday | O18: 40544
A19: 23 | B19: 40544 | C19: 1 | D19: 0 | E19: 1 | F19: 22 | G19: FALSE | H19: 6 | I19: 2 | J19: 0.4 | L19: LEFT(dteday,2) – Day | O19: =LEFT(B2,2) -> 40
A20: 31 | B20: 40545 | C20: 1 | D20: 0 | E20: 1 | F20: 7 | G20: FALSE | H20: 0 | I20: 2 | J20: 0.4 | L20: RIGHT(dteday,4) – Year | O20: =RIGHT(B3,2) -> 44
A21: 32 | B21: 40545 | C21: 1 | D21: 0 | E21: 1 | F21: 8 | G21: FALSE | H21: 0 | I21: 3 | J21: 0.4 | L21: LEN(dteday) – Characters in date string | O21: =LEN(B2) -> 5
A22: 421 | B22: 40562 | C22: 1 | D22: 0 | E22: 1 | F22: 13 | G22: FALSE | H22: 3 | I22: 1 | J22: 0.4 | L22: mid(dtedy2,2) | O22: =MID(B2,2,2) -> 05
A23: 422 | B23: 40562 | C23: 1 | D23: 0 | E23: 1 | F23: 14 | G23: FALSE | H23: 3 | I23: 1 | J23: 0.4
A24: 423 | B24: 40562 | C24: 1 | D24: 0 | E24: 1 | F24: 15 | G24: FALSE | H24: 3 | I24: 1 | J24: 0.4
A25: 11 | B25: 40544 | C25: 1 | D25: 0 | E25: 1 | F25: 10 | G25: FALSE | H25: 6 | I25: 1 | J25: 0.38
A26: 33 | B26: 40545 | C26: 1 | D26: 0 | E26: 1 | F26: 9 | G26: FALSE | H26: 0 | I26: 2 | J26: 0.38
A27: 424 | B27: 40562 | C27: 1 | D27: 0 | E27: 1 | F27: 16 | G27: FALSE | H27: 3 | I27: 1 | J27: 0.38
A28: 12 | B28: 40544 | C28: 1 | D28: 0 | E28: 1 | F28: 11 | G28: FALSE | H28: 6 | I28: 1 | J28: 0.36
A29: 34 | B29: 40545 | C29: 1 | D29: 0 | E29: 1 | F29: 10 | G29: FALSE | H29: 0 | I29: 2 | J29: 0.36
A30: 35 | B30: 40545 | C30: 1 | D30: 0 | E30: 1 | F30: 11 | G30: FALSE | H30: 0 | I30: 2 | J30: 0.36
A31: 36 | B31: 40545 | C31: 1 | D31: 0 | E31: 1 | F31: 12 | G31: FALSE | H31: 0 | I31: 2 | J31: 0.36
A32: 37 | B32: 40545 | C32: 1 | D32: 0 | E32: 1 | F32: 13 | G32: FALSE | H32: 0 | I32: 2 | J32: 0.36
A33: 38 | B33: 40545 | C33: 1 | D33: 0 | E33: 1 | F33: 14 | G33: FALSE | H33: 0 | I33: 3 | J33: 0.36
A34: 42 | B34: 40545 | C34: 1 | D34: 0 | E34: 1 | F34: 18 | G34: FALSE | H34: 0 | I34: 2 | J34: 0.36
... A611: 532 | B611: 40567 | C611: 1 | D611: 0 | E611: 1 | F611: 7 | G611: FALSE | H611: 1 | I611: 1 | J611: 0.02

Sheet dataset_2
A1: Unnamed: 0 | B1: instant | C1: atemp | D1: hum | E1: windspeed | F1: casual | G1: registered | H1: cnt | I1: check_cnt
A2: 439 | B2: 440 | C2: 0.2121 | D2: 0.55 | E2: 0.2836 | F2: 2 | G2: 247 | H2: 249 | I2: =SUM(Table2[[#This Row],[casual]],Table2[[#This Row],[registered]]) -> 249 | K2: 1. Conditional Formatting (Coloring Data)
A3: 555 | B3: 556 | C3: 0.1818 | D3: 0.74 | E3: 0.1343 | F3: 5 | G3: 233 | H3: 238 | I3: =SUM(Table2[[#This Row],[casual]],Table2[[#This Row],[registered]]) -> 238
A4: 565 | B4: 566 | C4: 0.3182 | D4: 0.49 | E4: 0.0896 | F4: 7 | G4: 218 | H4: 225 | I4: =SUM(Table2[[#This Row],[casual]],Table2[[#This Row],[registered]]) -> 225 | K4: windspeed Greater Than → 0.4 = Red colour fill
A5: 564 | B5: 565 | C5: 0.3333 | D5: 0.45 | E5: 0 | F5: 14 | G5: 208 | H5: 222 | I5: =SUM(Table2[[#This Row],[casual]],Table2[[#This Row],[registered]]) -> 222 | K5: atemp Above Average = Green colour
A6: 122 | B6: 123 | C6: 0.2273 | D6: 0.59 | E6: 0 | F6: 3 | G6: 216 | H6: 219 | I6: =SUM(Table2[[#This Row],[casual]],Table2[[#This Row],[registered]]) -> 219 | K6: hum- use colour scaler higest red colour
A7: 239 | B7: 240 | C7: 0.2121 | D7: 0.51 | E7: 0.0896 | F7: 3 | G7: 214 | H7: 217 | I7: =SUM(Table2[[#This Row],[casual]],Table2[[#This Row],[registered]]) -> 217 | K7: cnt top 15 = Red colour
A8: 463 | B8: 464 | C8: 0.1818 | D8: 0.47 | E8: 0.3284 | F8: 7 | G8: 210 | H8: 217 | I8: =SUM(Table2[[#This Row],[casual]],Table2[[#This Row],[registered]]) -> 217 | K8: check_cnt by adding casual & registered
A9: 448 | B9: 449 | C9: 0.3182 | D9: 0.49 | E9: 0.1045 | F9: 8 | G9: 207 | H9: 215 | I9: =SUM(Table2[[#This Row],[casual]],Table2[[#This Row],[registered]]) -> 215
A10: 85 | B10: 86 | C10: 0.2727 | D10: 0.48 | E10: 0.2239 | F10: 10 | G10: 202 | H10: 212 | I10: =SUM(Table2[[#This Row],[casual]],Table2[[#This Row],[registered]]) -> 212
A11: 145 | B11: 146 | C11: 0.197 | D11: 0.51 | E11: 0.2537 | F11: 20 | G11: 190 | H11: 210 | I11: =SUM(Table2[[#This Row],[casual]],Table2[[#This Row],[registered]]) -> 210 | K11: 2. Basic Aggregations on count
A12: 285 | B12: 286 | C12: 0.1364 | D12: 0.5 | E12: 0.194 | F12: 5 | G12: 197 | H12: 202 | I12: =SUM(Table2[[#This Row],[casual]],Table2[[#This Row],[registered]]) -> 202
A13: 415 | B13: 416 | C13: 0.2576 | D13: 0.93 | E13: 0.1045 | F13: 1 | G13: 196 | H13: 197 | I13: =SUM(Table2[[#This Row],[casual]],Table2[[#This Row],[registered]]) -> 197 | K13: sum of cnt | O13: =SUM(H:H) -> 33898
A14: 424 | B14: 425 | C14: 0.3333 | D14: 0.57 | E14: 0.3284 | F14: 7 | G14: 190 | H14: 197 | I14: =SUM(Table2[[#This Row],[casual]],Table2[[#This Row],[registered]]) -> 197 | K14: average of cnt | O14: =AVERAGE(H:H) -> 55.570492
A15: 99 | B15: 100 | C15: 0.1818 | D15: 0.4 | E15: 0.2985 | F15: 3 | G15: 192 | H15: 195 | I15: =SUM(Table2[[#This Row],[casual]],Table2[[#This Row],[registered]]) -> 195 | K15: count of cnt | O15: =COUNT(H:H) -> 610
A16: 108 | B16: 109 | C16: 0.2273 | D16: 0.38 | E16: 0.194 | F16: 4 | G16: 186 | H16: 190 | I16: =SUM(Table2[[#This Row],[casual]],Table2[[#This Row],[registered]]) -> 190
A17: 217 | B17: 218 | C17: 0.1212 | D17: 0.5 | E17: 0.2836 | F17: 4 | G17: 184 | H17: 188 | I17: =SUM(Table2[[#This Row],[casual]],Table2[[#This Row],[registered]]) -> 188
A18: 154 | B18: 155 | C18: 0.2576 | D18: 0.37 | E18: 0 | F18: 9 | G18: 178 | H18: 187 | I18: =SUM(Table2[[#This Row],[casual]],Table2[[#This Row],[registered]]) -> 187
A19: 449 | B19: 450 | C19: 0.2576 | D19: 0.56 | E19: 0.194 | F19: 1 | G19: 184 | H19: 185 | I19: =SUM(Table2[[#This Row],[casual]],Table2[[#This Row],[registered]]) -> 185
A20: 541 | B20: 542 | C20: 0.1212 | D20: 0.5 | E20: 0.2537 | F20: 6 | G20: 178 | H20: 184 | I20: =SUM(Table2[[#This Row],[casual]],Table2[[#This Row],[registered]]) -> 184
A21: 86 | B21: 87 | C21: 0.2576 | D21: 0.48 | E21: 0.194 | F21: 3 | G21: 179 | H21: 182 | I21: =SUM(Table2[[#This Row],[casual]],Table2[[#This Row],[registered]]) -> 182
A22: 76 | B22: 77 | C22: 0.1515 | D22: 0.69 | E22: 0.1642 | F22: 2 | G22: 177 | H22: 179 | I22: =SUM(Table2[[#This Row],[casual]],Table2[[#This Row],[registered]]) -> 179
A23: 226 | B23: 227 | C23: 0.2273 | D23: 0.4 | E23: 0.1045 | F23: 4 | G23: 174 | H23: 178 | I23: =SUM(Table2[[#This Row],[casual]],Table2[[#This Row],[registered]]) -> 178
A24: 532 | B24: 533 | C24: 0.1364 | D24: 0.49 | E24: 0 | F24: 6 | G24: 171 | H24: 177 | I24: =SUM(Table2[[#This Row],[casual]],Table2[[#This Row],[registered]]) -> 177
A25: 131 | B25: 132 | C25: 0.2273 | D25: 0.51 | E25: 0.1642 | F25: 9 | G25: 163 | H25: 172 | I25: =SUM(Table2[[#This Row],[casual]],Table2[[#This Row],[registered]]) -> 172
A26: 109 | B26: 110 | C26: 0.2424 | D26: 0.38 | E26: 0.1343 | F26: 3 | G26: 166 | H26: 169 | I26: =SUM(Table2[[#This Row],[casual]],Table2[[#This Row],[registered]]) -> 169
A27: 464 | B27: 465 | C27: 0.1818 | D27: 0.51 | E27: 0.3582 | F27: 7 | G27: 159 | H27: 166 | I27: =SUM(Table2[[#This Row],[casual]],Table2[[#This Row],[registered]]) -> 166
... A204: 561 | B204: 562 | C204: 0.3333 | D204: 0.45 | E204: 0 | F204: 11 | G204: 57 | H204: 68 | I204: =SUM(Table2[[#This Row],[casual]],Table2[[#This Row],[registered]]) -> 68
A205: 17 | B205: 18 | D205: 0.82 | E205: 0.2836 | F205: 15 | G205: 52 | H205: 67 | I205: =SUM(Table2[[#This Row],[casual]],Table2[[#This Row],[registered]]) -> 67
A206: 127 | B206: 128 | C206: 0.2727 | D206: 0.35 | E206: 0.1045 | F206: 12 | G206: 55 | H206: 67 | I206: =SUM(Table2[[#This Row],[casual]],Table2[[#This Row],[registered]]) -> 67
A207: 148 | B207: 149 | C207: 0.197 | D207: 0.4 | E207: 0.2239 | F207: 19 | G207: 48 | H207: 67 | I207: =SUM(Table2[[#This Row],[casual]],Table2[[#This Row],[registered]]) -> 67
A208: 366 | B208: 367 | C208: 0.2121 | D208: 0.4 | E208: 0.1642 | F208: 11 | G208: 56 | H208: 67 | I208: =SUM(Table2[[#This Row],[casual]],Table2[[#This Row],[registered]]) -> 67
A209: 495 | B209: 496 | C209: 0.197 | D209: 0.28 | E209: 0 | F209: 8 | G209: 59 | H209: 67 | I209: =SUM(Table2[[#This Row],[casual]],Table2[[#This Row],[registered]]) -> 67
A210: 40 | B210: 41 | C210: 0.3333 | D210: 0.57 | E210: 0.194 | F210: 7 | G210: 58 | H210: 65 | I210: =SUM(Table2[[#This Row],[casual]],Table2[[#This Row],[registered]]) -> 65
A211: 83 | B211: 84 | C211: 0.2727 | D211: 0.52 | E211: 0.2537 | F211: 17 | G211: 48 | H211: 65 | I211: =SUM(Table2[[#This Row],[casual]],Table2[[#This Row],[registered]]) -> 65
A212: 470 | B212: 471 | C212: 0.1212 | D212: 0.26 | E212: 0.4478 | F212: 4 | G212: 61 | H212: 65 | I212: =SUM(Table2[[#This Row],[casual]],Table2[[#This Row],[registered]]) -> 65
A213: 517 | B213: 518 | C213: 0.1364 | D213: 0.26 | E213: 0.3284 | F213: 9 | G213: 56 | H213: 65 | I213: =SUM(Table2[[#This Row],[casual]],Table2[[#This Row],[registered]]) -> 65
A214: 52 | B214: 53 | C214: 0.1364 | D214: 0.5 | E214: 0.194 | F214: 1 | G214: 63 | H214: 64 | I214: =SUM(Table2[[#This Row],[casual]],Table2[[#This Row],[registered]]) -> 64
A215: 297 | B215: 298 | C215: 0.1515 | D215: 0.47 | E215: 0.2239 | F215: 0 | G215: 64 | H215: 64 | I215: =SUM(Table2[[#This Row],[casual]],Table2[[#This Row],[registered]]) -> 64
A216: 314 | B216: 315 | C216: 0.2121 | D216: 0.41 | E216: 0.2836 | F216: 5 | G216: 59 | H216: 64 | I216: =SUM(Table2[[#This Row],[casual]],Table2[[#This Row],[registered]]) -> 64
...

Sheet dataset_3
A1: instant | B1: dteday | C1: season | D1: yr | E1: mnth | F1: hr | G1: holiday | H1: weekday | I1: weathersit | J1: temp | K1: atemp | L1: hum | M1: windspeed | N1: casual | O1: registered | P1: cnt
A2: 862 | B2: 40582 | C2: 1 | D2: 0 | E2: 2 | F2: 8 | G2: FALSE | H2: 2 | I2: 1 | J2: 0.24 | K2: 0.197 | L2: 0.56 | M2: 0.4925 | N2: 7 | O2: 236 | P2: 243 | R2: Basic Aggregations
A3: 838 | B3: 40581 | C3: 1 | D3: 0 | E3: 2 | F3: 8 | G3: FALSE | H3: 1 | I3: 2 | J3: 0.16 | K3: 0.2273 | L3: 1 | M3: 0 | N3: 7 | O3: 223 | P3: 230
A4: 766 | B4: 40578 | C4: 1 | D4: 0 | E4: 2 | F4: 8 | G4: FALSE | H4: 5 | I4: 1 | J4: 0.14 | K4: 0.1515 | L4: 0.74 | M4: 0.1343 | N4: 3 | O4: 217 | P4: 220 | R4: SUM OF REGSTERED | T4: =SUM(O:O) -> 22231
A5: 847 | B5: 40581 | C5: 1 | D5: 0 | E5: 2 | F5: 17 | G5: FALSE | H5: 1 | I5: 2 | J5: 0.32 | K5: 0.3182 | L5: 0.7 | M5: 0.1642 | N5: 9 | O5: 207 | P5: 216 | R5: SUM OF CNT | T5: =SUM(P:P) -> 24406
A6: 930 | B6: 40585 | C6: 1 | D6: 0 | E6: 2 | F6: 8 | G6: FALSE | H6: 5 | I6: 1 | J6: 0.1 | K6: 0.1212 | L6: 0.74 | M6: 0.1642 | N6: 4 | O6: 212 | P6: 216 | R6: SUM OF CASUAL | T6: =SUM(N:N) -> 2175
A7: 939 | B7: 40585 | C7: 1 | D7: 0 | E7: 2 | F7: 17 | G7: FALSE | H7: 5 | I7: 1 | J7: 0.3 | K7: 0.3333 | L7: 0.24 | M7: 0 | N7: 18 | O7: 193 | P7: 211 | R7: AVERGAE OF CNT | T7: =AVERAGE(P:P) -> 62.579487
A8: 775 | B8: 40578 | C8: 1 | D8: 0 | E8: 2 | F8: 17 | G8: FALSE | H8: 5 | I8: 2 | J8: 0.26 | K8: 0.2727 | L8: 0.56 | M8: 0.1343 | N8: 10 | O8: 195 | P8: 205 | R8: COUNT
A9: 885 | B9: 40583 | C9: 1 | D9: 0 | E9: 2 | F9: 8 | G9: FALSE | H9: 3 | I9: 1 | J9: 0.1 | K9: 0.1364 | L9: 0.42 | M9: 0 | N9: 1 | O9: 198 | P9: 199 | R9: COUNTIF( HOLIDAY TRUE) | T9: =COUNTIF(G2:G391,FALSE) -> 390
A10: 729 | B10: 40576 | C10: 1 | D10: 0 | E10: 2 | F10: 17 | G10: FALSE | H10: 3 | I10: 1 | J10: 0.36 | K10: 0.3182 | L10: 0.53 | M10: 0.5224 | N10: 7 | O10: 183 | P10: 190
A11: 743 | B11: 40577 | C11: 1 | D11: 0 | E11: 2 | F11: 8 | G11: FALSE | H11: 4 | I11: 1 | J11: 0.14 | K11: 0.1212 | L11: 0.5 | M11: 0.3582 | N11: 4 | O11: 184 | P11: 188
A12: 673 | B12: 40574 | C12: 1 | D12: 0 | E12: 1 | F12: 8 | G12: FALSE | H12: 1 | I12: 2 | J12: 0.16 | K12: 0.1364 | L12: 0.59 | M12: 0.2836 | N12: 3 | O12: 182 | P12: 185 | R12: TEXT Functions on dteday
A13: 730 | B13: 40576 | C13: 1 | D13: 0 | E13: 2 | F13: 18 | G13: FALSE | H13: 3 | I13: 1 | J13: 0.34 | K13: 0.2879 | L13: 0.42 | M13: 0.5522 | N13: 7 | O13: 175 | P13: 182
A14: 819 | B14: 40580 | C14: 1 | D14: 0 | E14: 2 | F14: 13 | G14: FALSE | H14: 0 | I14: 1 | J14: 0.34 | K14: 0.3636 | L14: 0.46 | M14: 0 | N14: 47 | O14: 135 | P14: 182 | R14: Sample dteday | U14: 40571
A15: 821 | B15: 40580 | C15: 1 | D15: 0 | E15: 2 | F15: 15 | G15: FALSE | H15: 0 | I15: 1 | J15: 0.34 | K15: 0.3485 | L15: 0.46 | M15: 0.0896 | N15: 52 | O15: 130 | P15: 182 | R15: LEFT(dteday,2) – Day | U15: =LEFT(B2,2) -> 40
A16: 908 | B16: 40584 | C16: 1 | D16: 0 | E16: 2 | F16: 8 | G16: FALSE | H16: 4 | I16: 1 | J16: 0.1 | K16: 0.0758 | L16: 0.49 | M16: 0.3284 | N16: 5 | O16: 173 | P16: 178 | R16: RIGHT(dteday,4) – Year | U16: =RIGHT(B2,2) -> 82
A17: 705 | B17: 40575 | C17: 1 | D17: 0 | E17: 2 | F17: 17 | G17: FALSE | H17: 2 | I17: 2 | J17: 0.24 | K17: 0.2879 | L17: 0.75 | M17: 0 | N17: 4 | O17: 172 | P17: 176 | R17: LEN(dteday) – Characters in date string | U17: =LEN(B2) -> 5
A18: 871 | B18: 40582 | C18: 1 | D18: 0 | E18: 2 | F18: 17 | G18: FALSE | H18: 2 | I18: 1 | J18: 0.22 | K18: 0.1818 | L18: 0.32 | M18: 0.5821 | N18: 4 | O18: 172 | P18: 176 | R18: mid(dtedy2,2) | U18: =MID(B2,2,2) -> 05
A19: 752 | B19: 40577 | C19: 1 | D19: 0 | E19: 2 | F19: 17 | G19: FALSE | H19: 4 | I19: 1 | J19: 0.2 | K19: 0.197 | L19: 0.4 | M19: 0.194 | N19: 5 | O19: 170 | P19: 175
A20: 848 | B20: 40581 | C20: 1 | D20: 0 | E20: 2 | F20: 18 | G20: FALSE | H20: 1 | I20: 2 | J20: 0.34 | K20: 0.3333 | L20: 0.66 | M20: 0.1343 | N20: 5 | O20: 170 | P20: 175 | R20: Conditional Formatting (Coloring Data)
A21: 818 | B21: 40580 | C21: 1 | D21: 0 | E21: 2 | F21: 12 | G21: FALSE | H21: 0 | I21: 1 | J21: 0.34 | K21: 0.3333 | L21: 0.46 | M21: 0 | N21: 48 | O21: 126 | P21: 174 | S21: weathersit = 3 → Red color (bad weather)
A22: 940 | B22: 40585 | C22: 1 | D22: 0 | E22: 2 | F22: 18 | G22: FALSE | H22: 5 | I22: 1 | J22: 0.28 | K22: 0.3182 | L22: 0.28 | M22: 0 | N22: 9 | O22: 165 | P22: 174 | S22: High temp → Red color
A23: 961 | B23: 40586 | C23: 1 | D23: 0 | E23: 2 | F23: 15 | G23: FALSE | H23: 6 | I23: 1 | J23: 0.34 | K23: 0.303 | L23: 0.29 | M23: 0.4179 | N23: 47 | O23: 127 | P23: 174 | S23: shoreted by cnt higest to lowsest to finding & Top 15 with color
A24: 895 | B24: 40583 | C24: 1 | D24: 0 | E24: 2 | F24: 18 | G24: FALSE | H24: 3 | I24: 2 | J24: 0.18 | K24: 0.1667 | L24: 0.47 | M24: 0.2985 | N24: 2 | O24: 168 | P24: 170
A25: 706 | B25: 40575 | C25: 1 | D25: 0 | E25: 2 | F25: 18 | G25: FALSE | H25: 2 | I25: 2 | J25: 0.24 | K25: 0.2576 | L25: 0.81 | M25: 0.1045 | N25: 3 | O25: 165 | P25: 168
A26: 894 | B26: 40583 | C26: 1 | D26: 0 | E26: 2 | F26: 17 | G26: FALSE | H26: 3 | I26: 2 | J26: 0.2 | K26: 0.197 | L26: 0.34 | M26: 0.2537 | N26: 9 | O26: 157 | P26: 166
A27: 917 | B27: 40584 | C27: 1 | D27: 0 | E27: 2 | F27: 17 | G27: FALSE | H27: 4 | I27: 1 | J27: 0.18 | K27: 0.1818 | L27: 0.26 | M27: 0.194 | N27: 6 | O27: 159 | P27: 165
A28: 984 | B28: 40587 | C28: 1 | D28: 0 | E28: 2 | F28: 15 | G28: FALSE | H28: 0 | I28: 2 | J28: 0.4 | K28: 0.4091 | L28: 0.3 | M28: 0.2985 | N28: 40 | O28: 122 | P28: 162
A29: 682 | B29: 40574 | C29: 1 | D29: 0 | E29: 1 | F29: 17 | G29: FALSE | H29: 1 | I29: 2 | J29: 0.16 | K29: 0.1515 | L29: 0.59 | M29: 0.194 | N29: 6 | O29: 155 | P29: 161
A30: 820 | B30: 40580 | C30: 1 | D30: 0 | E30: 2 | F30: 14 | G30: FALSE | H30: 0 | I30: 1 | J30: 0.34 | K30: 0.3485 | L30: 0.46 | M30: 0.0896 | N30: 47 | O30: 114 | P30: 161
A31: 983 | B31: 40587 | C31: 1 | D31: 0 | E31: 2 | F31: 14 | G31: FALSE | H31: 0 | I31: 2 | J31: 0.4 | K31: 0.4091 | L31: 0.3 | M31: 0.4179 | N31: 51 | O31: 110 | P31: 161
A32: 918 | B32: 40584 | C32: 1 | D32: 0 | E32: 2 | F32: 18 | G32: FALSE | H32: 4 | I32: 1 | J32: 0.16 | K32: 0.1818 | L32: 0.28 | M32: 0.1343 | N32: 3 | O32: 157 | P32: 160
A33: 822 | B33: 40580 | C33: 1 | D33: 0 | E33: 2 | F33: 16 | G33: FALSE | H33: 0 | I33: 1 | J33: 0.34 | K33: 0.3485 | L33: 0.49 | M33: 0.1045 | N33: 42 | O33: 115 | P33: 157
A34: 683 | B34: 40574 | C34: 1 | D34: 0 | E34: 1 | F34: 18 | G34: FALSE | H34: 1 | I34: 2 | J34: 0.16 | K34: 0.1515 | L34: 0.55 | M34: 0.2239 | N34: 3 | O34: 153 | P34: 156
A35: 720 | B35: 40576 | C35: 1 | D35: 0 | E35: 2 | F35: 8 | G35: FALSE | H35: 3 | I35: 3 | J35: 0.22 | K35: 0.2121 | L35: 0.93 | M35: 0.2239 | N35: 1 | O35: 154 | P35: 155
... A391: 951 | B391: 40586 | C391: 1 | D391: 0 | E391: 2 | F391: 5 | G391: FALSE | H391: 6 | I391: 1 | J391: 0.12 | K391: 0.1667 | L391: 0.74 | M391: 0.0896 | N391: 0 | O391: 1 | P391: 1

Sheet clean data
A1: instant | B1: dteday | C1: mnth | D1: hr | E1: holiday | F1: weekday | G1: weathersit | H1: temp | I1: atemp | J1: hum | K1: windspeed | L1: casual | M1: registered | N1: cnt | O1: weather_category | P1: Week_days | Q1: week_type | R1: Time period | S1: temp_cat | T1: rolling_mean_24h | U1: rolling_std_24h | V1: zscore_24h | W1: Anomaly_flag
A2: 1 | B2: 40544 | C2: 1 | D2: 0 | E2: FALSE | F2: 6 | G2: 1 | H2: 0.24 | I2: 0.2879 | J2: 0.81 | K2: 0 | L2: 3 | M2: 13 | N2: 16 | O2: =VLOOKUP(G2,calculate_field!$B$2:$C$5,2,FALSE) -> Clear/Partly Cloudy | P2: =CHOOSE(F2+1,"Sunday","Monday","Tuesday","Wednesday","Thursday","Friday","Saturday") -> Saturday | Q2: =IF(OR(F2=0,F2=6),"Weekend","Weekday") -> Weekend | R2: =IF(D2<6,"Night",IF(D2<12,"Morning",IF(D2<17,"Afternoon",IF(D2<21,"Evening","Night")))) -> Night | S2: =INDEX(calculate_field!$F$2:$F$4, MATCH(H2, calculate_field!$E$2:$E$4, 1)) -> Mild | T2: =AVERAGE(N2:N25) -> 41.041667 | U2: =_xlfn.STDEV.S(N2:N25) -> 34.292196 | V2: =(N25-T25)/U25 -> 0.13725505 | W2: =IFERROR(ABS(V18)>1.5,FALSE) -> FALSE
A3: 2 | B3: 40544 | C3: 1 | D3: 1 | E3: FALSE | F3: 6 | G3: 1 | H3: 0.22 | I3: 0.2727 | J3: 0.8 | K3: 0 | L3: 8 | M3: 32 | N3: 40 | O3: =VLOOKUP(G3,calculate_field!$B$2:$C$5,2,FALSE) -> Clear/Partly Cloudy | P3: =CHOOSE(F3+1,"Sunday","Monday","Tuesday","Wednesday","Thursday","Friday","Saturday") -> Saturday | Q3: =IF(OR(F3=0,F3=6),"Weekend","Weekday") -> Weekend | R3: =IF(D3<6,"Night",IF(D3<12,"Morning",IF(D3<17,"Afternoon",IF(D3<21,"Evening","Night")))) -> Night | S3: =INDEX(calculate_field!$F$2:$F$4, MATCH(H3, calculate_field!$E$2:$E$4, 1)) -> Mild | T3: =AVERAGE(N3:N26) -> 41.083333 | U3: =_xlfn.STDEV.S(N3:N26) -> 34.26104 | V3: =(N26-T26)/U26 -> -0.55723965 | W3: =IFERROR(ABS(V19)>1.5,FALSE) -> FALSE
A4: 3 | B4: 40544 | C4: 1 | D4: 2 | E4: FALSE | F4: 6 | G4: 1 | H4: 0.22 | I4: 0.2727 | J4: 0.8 | K4: 0 | L4: 5 | M4: 27 | N4: 32 | O4: =VLOOKUP(G4,calculate_field!$B$2:$C$5,2,FALSE) -> Clear/Partly Cloudy | P4: =CHOOSE(F4+1,"Sunday","Monday","Tuesday","Wednesday","Thursday","Friday","Saturday") -> Saturday | Q4: =IF(OR(F4=0,F4=6),"Weekend","Weekday") -> Weekend | R4: =IF(D4<6,"Night",IF(D4<12,"Morning",IF(D4<17,"Afternoon",IF(D4<21,"Evening","Night")))) -> Night | S4: =INDEX(calculate_field!$F$2:$F$4, MATCH(H4, calculate_field!$E$2:$E$4, 1)) -> Mild | T4: =AVERAGE(N4:N27) -> 40.125 | U4: =_xlfn.STDEV.S(N4:N27) -> 34.612529 | V4: =(N27-T27)/U27 -> -0.52709109 | W4: =IFERROR(ABS(V20)>1.5,FALSE) -> FALSE
A5: 4 | B5: 40544 | C5: 1 | D5: 3 | E5: FALSE | F5: 6 | G5: 1 | H5: 0.24 | I5: 0.2879 | J5: 0.75 | K5: 0 | L5: 3 | M5: 10 | N5: 13 | O5: =VLOOKUP(G5,calculate_field!$B$2:$C$5,2,FALSE) -> Clear/Partly Cloudy | P5: =CHOOSE(F5+1,"Sunday","Monday","Tuesday","Wednesday","Thursday","Friday","Saturday") -> Saturday | Q5: =IF(OR(F5=0,F5=6),"Weekend","Weekday") -> Weekend | R5: =IF(D5<6,"Night",IF(D5<12,"Morning",IF(D5<17,"Afternoon",IF(D5<21,"Evening","Night")))) -> Night | S5: =INDEX(calculate_field!$F$2:$F$4, MATCH(H5, calculate_field!$E$2:$E$4, 1)) -> Mild | T5: =AVERAGE(N5:N28) -> 39.166667 | U5: =_xlfn.STDEV.S(N5:N28) -> 35.161326 | V5: =(N28-T28)/U28 -> -0.75587246 | W5: =IFERROR(ABS(V21)>1.5,FALSE) -> FALSE
A6: 5 | B6: 40544 | C6: 1 | D6: 4 | E6: FALSE | F6: 6 | G6: 1 | H6: 0.24 | I6: 0.2879 | J6: 0.75 | K6: 0 | L6: 0 | M6: 1 | N6: 1 | O6: =VLOOKUP(G6,calculate_field!$B$2:$C$5,2,FALSE) -> Clear/Partly Cloudy | P6: =CHOOSE(F6+1,"Sunday","Monday","Tuesday","Wednesday","Thursday","Friday","Saturday") -> Saturday | Q6: =IF(OR(F6=0,F6=6),"Weekend","Weekday") -> Weekend | R6: =IF(D6<6,"Night",IF(D6<12,"Morning",IF(D6<17,"Afternoon",IF(D6<21,"Evening","Night")))) -> Night | S6: =INDEX(calculate_field!$F$2:$F$4, MATCH(H6, calculate_field!$E$2:$E$4, 1)) -> Mild | T6: =AVERAGE(N6:N29) -> 38.875 | U6: =_xlfn.STDEV.S(N6:N29) -> 35.415929 | V6: =(N29-T29)/U29 -> -0.839106 | W6: =IFERROR(ABS(V22)>1.5,FALSE) -> FALSE
A7: 6 | B7: 40544 | C7: 1 | D7: 5 | E7: FALSE | F7: 6 | G7: 2 | H7: 0.24 | I7: 0.2576 | J7: 0.75 | K7: 0.0896 | L7: 0 | M7: 1 | N7: 1 | O7: =VLOOKUP(G7,calculate_field!$B$2:$C$5,2,FALSE) -> Mist / cloudy | P7: =CHOOSE(F7+1,"Sunday","Monday","Tuesday","Wednesday","Thursday","Friday","Saturday") -> Saturday | Q7: =IF(OR(F7=0,F7=6),"Weekend","Weekday") -> Weekend | R7: =IF(D7<6,"Night",IF(D7<12,"Morning",IF(D7<17,"Afternoon",IF(D7<21,"Evening","Night")))) -> Night | S7: =INDEX(calculate_field!$F$2:$F$4, MATCH(H7, calculate_field!$E$2:$E$4, 1)) -> Mild | T7: =AVERAGE(N7:N30) -> 38.958333 | U7: =_xlfn.STDEV.S(N7:N30) -> 35.325172 | V7: =(N30-T30)/U30 -> -0.98361265 | W7: =IFERROR(ABS(V23)>1.5,FALSE) -> FALSE
A8: 7 | B8: 40544 | C8: 1 | D8: 6 | E8: FALSE | F8: 6 | G8: 1 | H8: 0.22 | I8: 0.2727 | J8: 0.8 | K8: 0 | L8: 2 | M8: 0 | N8: 2 | O8: =VLOOKUP(G8,calculate_field!$B$2:$C$5,2,FALSE) -> Clear/Partly Cloudy | P8: =CHOOSE(F8+1,"Sunday","Monday","Tuesday","Wednesday","Thursday","Friday","Saturday") -> Saturday | Q8: =IF(OR(F8=0,F8=6),"Weekend","Weekday") -> Weekend | R8: =IF(D8<6,"Night",IF(D8<12,"Morning",IF(D8<17,"Afternoon",IF(D8<21,"Evening","Night")))) -> Morning | S8: =INDEX(calculate_field!$F$2:$F$4, MATCH(H8, calculate_field!$E$2:$E$4, 1)) -> Mild | T8: =AVERAGE(N8:N31) -> 39 | U8: =_xlfn.STDEV.S(N8:N31) -> 35.279012 | V8: =(N31-T31)/U31 -> -1.1021215 | W8: =IFERROR(ABS(V24)>1.5,FALSE) -> FALSE
A9: 8 | B9: 40544 | C9: 1 | D9: 7 | E9: FALSE | F9: 6 | G9: 1 | H9: 0.2 | I9: 0.2576 | J9: 0.86 | K9: 0 | L9: 1 | M9: 2 | N9: 3 | O9: =VLOOKUP(G9,calculate_field!$B$2:$C$5,2,FALSE) -> Clear/Partly Cloudy | P9: =CHOOSE(F9+1,"Sunday","Monday","Tuesday","Wednesday","Thursday","Friday","Saturday") -> Saturday | Q9: =IF(OR(F9=0,F9=6),"Weekend","Weekday") -> Weekend | R9: =IF(D9<6,"Night",IF(D9<12,"Morning",IF(D9<17,"Afternoon",IF(D9<21,"Evening","Night")))) -> Morning | S9: =INDEX(calculate_field!$F$2:$F$4, MATCH(H9, calculate_field!$E$2:$E$4, 1)) -> Mild | T9: =AVERAGE(N9:N32) -> 38.958333 | U9: =_xlfn.STDEV.S(N9:N32) -> 35.325172 | V9: =(N32-T32)/U32 -> -1.0755272 | W9: =IFERROR(ABS(V25)>1.5,FALSE) -> FALSE
A10: 9 | B10: 40544 | C10: 1 | D10: 8 | E10: FALSE | F10: 6 | G10: 1 | H10: 0.24 | I10: =IF(I2="", _xlfn.MODE.SNGL($I$2:$I$1000), I2) -> 0.2879 | J10: 0.75 | K10: 0 | L10: 1 | M10: 7 | N10: 8 | O10: =VLOOKUP(G10,calculate_field!$B$2:$C$5,2,FALSE) -> Clear/Partly Cloudy | P10: =CHOOSE(F10+1,"Sunday","Monday","Tuesday","Wednesday","Thursday","Friday","Saturday") -> Saturday | Q10: =IF(OR(F10=0,F10=6),"Weekend","Weekday") -> Weekend | R10: =IF(D10<6,"Night",IF(D10<12,"Morning",IF(D10<17,"Afternoon",IF(D10<21,"Evening","Night")))) -> Morning | S10: =INDEX(calculate_field!$F$2:$F$4, MATCH(H10, calculate_field!$E$2:$E$4, 1)) -> Mild | T10: =AVERAGE(N10:N33) -> 39.166667 | U10: =_xlfn.STDEV.S(N10:N33) -> 35.11802 | V10: =(N33-T33)/U33 -> -0.98483057 | W10: =IFERROR(ABS(V26)>1.5,FALSE) -> FALSE
A11: 10 | B11: 40544 | C11: 1 | D11: 9 | E11: FALSE | F11: 6 | G11: 1 | H11: 0.32 | I11: 0.3485 | J11: 0.76 | K11: 0 | L11: 8 | M11: 6 | N11: 14 | O11: =VLOOKUP(G11,calculate_field!$B$2:$C$5,2,FALSE) -> Clear/Partly Cloudy | P11: =CHOOSE(F11+1,"Sunday","Monday","Tuesday","Wednesday","Thursday","Friday","Saturday") -> Saturday | Q11: =IF(OR(F11=0,F11=6),"Weekend","Weekday") -> Weekend | R11: =IF(D11<6,"Night",IF(D11<12,"Morning",IF(D11<17,"Afternoon",IF(D11<21,"Evening","Night")))) -> Morning | S11: =INDEX(calculate_field!$F$2:$F$4, MATCH(H11, calculate_field!$E$2:$E$4, 1)) -> Warm | T11: =AVERAGE(N11:N34) -> 39.666667 | U11: =_xlfn.STDEV.S(N11:N34) -> 34.73836 | V11: =(N34-T34)/U34 -> -0.72541658 | W11: =IFERROR(ABS(V27)>1.5,FALSE) -> FALSE
A12: 11 | B12: 40544 | C12: 1 | D12: 10 | E12: FALSE | F12: 6 | G12: 1 | H12: 0.38 | I12: 0.3939 | J12: 0.76 | K12: 0.2537 | L12: 12 | M12: 24 | N12: 36 | O12: =VLOOKUP(G12,calculate_field!$B$2:$C$5,2,FALSE) -> Clear/Partly Cloudy | P12: =CHOOSE(F12+1,"Sunday","Monday","Tuesday","Wednesday","Thursday","Friday","Saturday") -> Saturday | Q12: =IF(OR(F12=0,F12=6),"Weekend","Weekday") -> Weekend | R12: =IF(D12<6,"Night",IF(D12<12,"Morning",IF(D12<17,"Afternoon",IF(D12<21,"Evening","Night")))) -> Morning | S12: =INDEX(calculate_field!$F$2:$F$4, MATCH(H12, calculate_field!$E$2:$E$4, 1)) -> Warm | T12: =AVERAGE(N12:N35) -> 41.291667 | U12: =_xlfn.STDEV.S(N12:N35) -> 34.396005 | V12: =(N35-T35)/U35 -> 0.12669407 | W12: =IFERROR(ABS(V28)>1.5,FALSE) -> FALSE
A13: 12 | B13: 40544 | C13: 1 | D13: 11 | E13: FALSE | F13: 6 | G13: 1 | H13: 0.36 | I13: 0.3333 | J13: 0.81 | K13: 0.2836 | L13: 26 | M13: 30 | N13: 56 | O13: =VLOOKUP(G13,calculate_field!$B$2:$C$5,2,FALSE) -> Clear/Partly Cloudy | P13: =CHOOSE(F13+1,"Sunday","Monday","Tuesday","Wednesday","Thursday","Friday","Saturday") -> Saturday | Q13: =IF(OR(F13=0,F13=6),"Weekend","Weekday") -> Weekend | R13: =IF(D13<6,"Night",IF(D13<12,"Morning",IF(D13<17,"Afternoon",IF(D13<21,"Evening","Night")))) -> Morning | S13: =INDEX(calculate_field!$F$2:$F$4, MATCH(H13, calculate_field!$E$2:$E$4, 1)) -> Warm | T13: =AVERAGE(N13:N36) -> 42.708333 | U13: =_xlfn.STDEV.S(N13:N36) -> 34.865554 | V13: =(N36-T36)/U36 -> 0.57791492 | W13: =IFERROR(ABS(V29)>1.5,FALSE) -> FALSE
A14: 13 | B14: 40544 | C14: 1 | D14: 12 | E14: FALSE | F14: 6 | G14: 1 | H14: 0.42 | I14: 0.4242 | J14: 0.77 | K14: 0.2836 | L14: 29 | M14: 55 | N14: 84 | O14: =VLOOKUP(G14,calculate_field!$B$2:$C$5,2,FALSE) -> Clear/Partly Cloudy | P14: =CHOOSE(F14+1,"Sunday","Monday","Tuesday","Wednesday","Thursday","Friday","Saturday") -> Saturday | Q14: =IF(OR(F14=0,F14=6),"Weekend","Weekday") -> Weekend | R14: =IF(D14<6,"Night",IF(D14<12,"Morning",IF(D14<17,"Afternoon",IF(D14<21,"Evening","Night")))) -> Afternoon | S14: =INDEX(calculate_field!$F$2:$F$4, MATCH(H14, calculate_field!$E$2:$E$4, 1)) -> Warm | T14: =AVERAGE(N14:N37) -> 44.25 | U14: =_xlfn.STDEV.S(N14:N37) -> 36.268623 | V14: =(N37-T37)/U37 -> 1.2171015 | W14: =IFERROR(ABS(V30)>1.5,FALSE) -> FALSE
A15: 14 | B15: 40544 | C15: 1 | D15: 13 | E15: FALSE | F15: 6 | G15: 2 | H15: 0.46 | I15: 0.4545 | J15: 0.72 | K15: 0.2985 | L15: 47 | M15: 47 | N15: 94 | O15: =VLOOKUP(G15,calculate_field!$B$2:$C$5,2,FALSE) -> Mist / cloudy | P15: =CHOOSE(F15+1,"Sunday","Monday","Tuesday","Wednesday","Thursday","Friday","Saturday") -> Saturday | Q15: =IF(OR(F15=0,F15=6),"Weekend","Weekday") -> Weekend | R15: =IF(D15<6,"Night",IF(D15<12,"Morning",IF(D15<17,"Afternoon",IF(D15<21,"Evening","Night")))) -> Afternoon | S15: =INDEX(calculate_field!$F$2:$F$4, MATCH(H15, calculate_field!$E$2:$E$4, 1)) -> Warm | T15: =AVERAGE(N15:N38) -> 43.875 | U15: =_xlfn.STDEV.S(N15:N38) -> 35.884249 | V15: =(N38-T38)/U38 -> 0.75988629 | W15: =IFERROR(ABS(V31)>1.5,FALSE) -> FALSE
A16: 15 | B16: 40544 | C16: 1 | D16: 14 | E16: FALSE | F16: 6 | G16: 2 | H16: 0.46 | I16: 0.4545 | J16: 0.72 | K16: 0.2836 | L16: 35 | M16: 71 | N16: 106 | O16: =VLOOKUP(G16,calculate_field!$B$2:$C$5,2,FALSE) -> Mist / cloudy | P16: =CHOOSE(F16+1,"Sunday","Monday","Tuesday","Wednesday","Thursday","Friday","Saturday") -> Saturday | Q16: =IF(OR(F16=0,F16=6),"Weekend","Weekday") -> Weekend | R16: =IF(D16<6,"Night",IF(D16<12,"Morning",IF(D16<17,"Afternoon",IF(D16<21,"Evening","Night")))) -> Afternoon | S16: =INDEX(calculate_field!$F$2:$F$4, MATCH(H16, calculate_field!$E$2:$E$4, 1)) -> Warm | T16: =AVERAGE(N16:N39) -> 42.416667 | U16: =_xlfn.STDEV.S(N16:N39) -> 34.44077 | V16: =(N39-T39)/U39 -> 0.32005706 | W16: =IFERROR(ABS(V32)>1.5,FALSE) -> TRUE
A17: 16 | B17: 40544 | C17: 1 | D17: 15 | E17: FALSE | F17: 6 | G17: 2 | H17: 0.44 | I17: 0.4394 | J17: 0.77 | K17: 0.2985 | L17: 40 | M17: 70 | N17: 110 | O17: =VLOOKUP(G17,calculate_field!$B$2:$C$5,2,FALSE) -> Mist / cloudy | P17: =CHOOSE(F17+1,"Sunday","Monday","Tuesday","Wednesday","Thursday","Friday","Saturday") -> Saturday | Q17: =IF(OR(F17=0,F17=6),"Weekend","Weekday") -> Weekend | R17: =IF(D17<6,"Night",IF(D17<12,"Morning",IF(D17<17,"Afternoon",IF(D17<21,"Evening","Night")))) -> Afternoon | S17: =INDEX(calculate_field!$F$2:$F$4, MATCH(H17, calculate_field!$E$2:$E$4, 1)) -> Warm | T17: =AVERAGE(N17:N40) -> 41.083333 | U17: =_xlfn.STDEV.S(N17:N40) -> 32.433097 | V17: =(N40-T40)/U40 -> 0.70986937 | W17: =IFERROR(ABS(V33)>1.5,FALSE) -> FALSE
A18: 17 | B18: 40544 | C18: 1 | D18: 16 | E18: FALSE | F18: 6 | G18: 2 | H18: 0.42 | I18: 0.4242 | J18: 0.82 | K18: 0.2985 | L18: 41 | M18: 52 | N18: 93 | O18: =VLOOKUP(G18,calculate_field!$B$2:$C$5,2,FALSE) -> Mist / cloudy | P18: =CHOOSE(F18+1,"Sunday","Monday","Tuesday","Wednesday","Thursday","Friday","Saturday") -> Saturday | Q18: =IF(OR(F18=0,F18=6),"Weekend","Weekday") -> Weekend | R18: =IF(D18<6,"Night",IF(D18<12,"Morning",IF(D18<17,"Afternoon",IF(D18<21,"Evening","Night")))) -> Afternoon | S18: =INDEX(calculate_field!$F$2:$F$4, MATCH(H18, calculate_field!$E$2:$E$4, 1)) -> Warm | T18: =AVERAGE(N18:N41) -> 39.666667 | U18: =_xlfn.STDEV.S(N18:N41) -> 29.938584 | V18: =(N41-T41)/U41 -> 0.57461653 | W18: =IFERROR(ABS(V34)>1.5,FALSE) -> FALSE
A19: 18 | B19: 40544 | C19: 1 | D19: 17 | E19: FALSE | F19: 6 | G19: 2 | H19: 0.44 | I19: =IF(I2="", _xlfn.MODE.SNGL($I$2:$I$1000), I2) -> 0.2879 | J19: 0.82 | K19: 0.2836 | L19: 15 | M19: 52 | N19: 67 | O19: =VLOOKUP(G19,calculate_field!$B$2:$C$5,2,FALSE) -> Mist / cloudy | P19: =CHOOSE(F19+1,"Sunday","Monday","Tuesday","Wednesday","Thursday","Friday","Saturday") -> Saturday | Q19: =IF(OR(F19=0,F19=6),"Weekend","Weekday") -> Weekend | R19: =IF(D19<6,"Night",IF(D19<12,"Morning",IF(D19<17,"Afternoon",IF(D19<21,"Evening","Night")))) -> Evening | S19: =INDEX(calculate_field!$F$2:$F$4, MATCH(H19, calculate_field!$E$2:$E$4, 1)) -> Warm | T19: =AVERAGE(N19:N42) -> 38.5 | U19: =_xlfn.STDEV.S(N19:N42) -> 28.268895 | V19: =(N42-T42)/U42 -> 0.21050023 | W19: =IFERROR(ABS(V35)>1.5,FALSE) -> FALSE
A20: 19 | B20: 40544 | C20: 1 | D20: 18 | E20: FALSE | F20: 6 | G20: 3 | H20: 0.42 | I20: 0.4242 | J20: 0.88 | K20: 0.2537 | L20: 9 | M20: 26 | N20: 35 | O20: =VLOOKUP(G20,calculate_field!$B$2:$C$5,2,FALSE) -> Light Snow / Rain | P20: =CHOOSE(F20+1,"Sunday","Monday","Tuesday","Wednesday","Thursday","Friday","Saturday") -> Saturday | Q20: =IF(OR(F20=0,F20=6),"Weekend","Weekday") -> Weekend | R20: =IF(D20<6,"Night",IF(D20<12,"Morning",IF(D20<17,"Afternoon",IF(D20<21,"Evening","Night")))) -> Evening | S20: =INDEX(calculate_field!$F$2:$F$4, MATCH(H20, calculate_field!$E$2:$E$4, 1)) -> Warm | T20: =AVERAGE(N20:N43) -> 37.916667 | U20: =_xlfn.STDEV.S(N20:N43) -> 27.795709 | V20: =(N43-T43)/U43 -> -0.080599676 | W20: =IFERROR(ABS(V36)>1.5,FALSE) -> FALSE
A21: 20 | B21: 40544 | C21: 1 | D21: 19 | E21: FALSE | F21: 6 | G21: 3 | H21: 0.42 | I21: 0.4242 | J21: 0.88 | K21: 0.2537 | L21: 6 | M21: 31 | N21: 37 | O21: =VLOOKUP(G21,calculate_field!$B$2:$C$5,2,FALSE) -> Light Snow / Rain | P21: =CHOOSE(F21+1,"Sunday","Monday","Tuesday","Wednesday","Thursday","Friday","Saturday") -> Saturday | Q21: =IF(OR(F21=0,F21=6),"Weekend","Weekday") -> Weekend | R21: =IF(D21<6,"Night",IF(D21<12,"Morning",IF(D21<17,"Afternoon",IF(D21<21,"Evening","Night")))) -> Evening | S21: =INDEX(calculate_field!$F$2:$F$4, MATCH(H21, calculate_field!$E$2:$E$4, 1)) -> Warm | T21: =AVERAGE(N21:N44) -> 37.708333 | U21: =_xlfn.STDEV.S(N21:N44) -> 27.837227 | V21: =(N44-T44)/U44 -> -0.55300621 | W21: =IFERROR(ABS(V37)>1.5,FALSE) -> FALSE
A22: 21 | B22: 40544 | C22: 1 | D22: 20 | E22: FALSE | F22: 6 | G22: 2 | H22: 0.4 | I22: 0.4091 | J22: 0.87 | K22: 0.2537 | L22: 11 | M22: 25 | N22: 36 | O22: =VLOOKUP(G22,calculate_field!$B$2:$C$5,2,FALSE) -> Mist / cloudy | P22: =CHOOSE(F22+1,"Sunday","Monday","Tuesday","Wednesday","Thursday","Friday","Saturday") -> Saturday | Q22: =IF(OR(F22=0,F22=6),"Weekend","Weekday") -> Weekend | R22: =IF(D22<6,"Night",IF(D22<12,"Morning",IF(D22<17,"Afternoon",IF(D22<21,"Evening","Night")))) -> Evening | S22: =INDEX(calculate_field!$F$2:$F$4, MATCH(H22, calculate_field!$E$2:$E$4, 1)) -> Warm | T22: =AVERAGE(N22:N45) -> 37.083333 | U22: =_xlfn.STDEV.S(N22:N45) -> 28.021601 | V22: =(N45-T45)/U45 -> -0.741405 | W22: =IFERROR(ABS(V38)>1.5,FALSE) -> FALSE
A23: 22 | B23: 40544 | C23: 1 | D23: 21 | E23: FALSE | F23: 6 | G23: 2 | H23: 0.4 | I23: 0.4091 | J23: 0.87 | K23: 0.194 | L23: 3 | M23: 31 | N23: 34 | O23: =VLOOKUP(G23,calculate_field!$B$2:$C$5,2,FALSE) -> Mist / cloudy | P23: =CHOOSE(F23+1,"Sunday","Monday","Tuesday","Wednesday","Thursday","Friday","Saturday") -> Saturday | Q23: =IF(OR(F23=0,F23=6),"Weekend","Weekday") -> Weekend | R23: =IF(D23<6,"Night",IF(D23<12,"Morning",IF(D23<17,"Afternoon",IF(D23<21,"Evening","Night")))) -> Night | S23: =INDEX(calculate_field!$F$2:$F$4, MATCH(H23, calculate_field!$E$2:$E$4, 1)) -> Warm | T23: =AVERAGE(N23:N46) -> 36.875 | U23: =_xlfn.STDEV.S(N23:N46) -> 28.04858 | V23: =(N46-T46)/U46 -> -0.5524916 | W23: =IFERROR(ABS(V39)>1.5,FALSE) -> FALSE
A24: 23 | B24: 40544 | C24: 1 | D24: 22 | E24: FALSE | F24: 6 | G24: 2 | H24: 0.4 | I24: 0.4091 | J24: 0.94 | K24: 0.2239 | L24: 11 | M24: 17 | N24: 28 | O24: =VLOOKUP(G24,calculate_field!$B$2:$C$5,2,FALSE) -> Mist / cloudy | P24: =CHOOSE(F24+1,"Sunday","Monday","Tuesday","Wednesday","Thursday","Friday","Saturday") -> Saturday | Q24: =IF(OR(F24=0,F24=6),"Weekend","Weekday") -> Weekend | R24: =IF(D24<6,"Night",IF(D24<12,"Morning",IF(D24<17,"Afternoon",IF(D24<21,"Evening","Night")))) -> Night | S24: =INDEX(calculate_field!$F$2:$F$4, MATCH(H24, calculate_field!$E$2:$E$4, 1)) -> Warm | T24: =AVERAGE(N24:N47) -> 35.833333 | U24: =_xlfn.STDEV.S(N24:N47) -> 28.618429 | V24: =(N47-T47)/U47 -> -0.97889468 | W24: =IFERROR(ABS(V40)>1.5,FALSE) -> FALSE
A25: 24 | B25: 40544 | C25: 1 | D25: 23 | E25: FALSE | F25: 6 | G25: 2 | H25: 0.46 | I25: =IF(I8="", _xlfn.MODE.SNGL($I$2:$I$1000), I8) -> 0.2727 | J25: 0.88 | K25: 0.2985 | L25: 15 | M25: 24 | N25: 39 | O25: =VLOOKUP(G25,calculate_field!$B$2:$C$5,2,FALSE) -> Mist / cloudy | P25: =CHOOSE(F25+1,"Sunday","Monday","Tuesday","Wednesday","Thursday","Friday","Saturday") -> Saturday | Q25: =IF(OR(F25=0,F25=6),"Weekend","Weekday") -> Weekend | R25: =IF(D25<6,"Night",IF(D25<12,"Morning",IF(D25<17,"Afternoon",IF(D25<21,"Evening","Night")))) -> Night | S25: =INDEX(calculate_field!$F$2:$F$4, MATCH(H25, calculate_field!$E$2:$E$4, 1)) -> Warm | T25: =AVERAGE(N25:N48) -> 35 | U25: =_xlfn.STDEV.S(N25:N48) -> 29.142827 | V25: =(N48-T48)/U48 -> -0.9923361 | W25: =IFERROR(ABS(V41)>1.5,FALSE) -> FALSE
A26: 25 | B26: 40545 | C26: 1 | D26: 0 | E26: FALSE | F26: 0 | G26: 2 | H26: 0.46 | I26: 0.4545 | J26: 0.88 | K26: 0.2985 | L26: 4 | M26: 13 | N26: 17 | O26: =VLOOKUP(G26,calculate_field!$B$2:$C$5,2,FALSE) -> Mist / cloudy | P26: =CHOOSE(F26+1,"Sunday","Monday","Tuesday","Wednesday","Thursday","Friday","Saturday") -> Sunday | Q26: =IF(OR(F26=0,F26=6),"Weekend","Weekday") -> Weekend | R26: =IF(D26<6,"Night",IF(D26<12,"Morning",IF(D26<17,"Afternoon",IF(D26<21,"Evening","Night")))) -> Night | S26: =INDEX(calculate_field!$F$2:$F$4, MATCH(H26, calculate_field!$E$2:$E$4, 1)) -> Warm | T26: =AVERAGE(N26:N49) -> 33.583333 | U26: =_xlfn.STDEV.S(N26:N49) -> 29.759787 | V26: =(N49-T49)/U49 -> -1.0425127 | W26: =IFERROR(ABS(V42)>1.5,FALSE) -> FALSE
A27: 26 | B27: 40545 | C27: 1 | D27: 1 | E27: FALSE | F27: 0 | G27: 2 | H27: 0.44 | I27: 0.4394 | J27: 0.94 | K27: 0.2537 | L27: 1 | M27: 16 | N27: 17 | O27: =VLOOKUP(G27,calculate_field!$B$2:$C$5,2,FALSE) -> Mist / cloudy | P27: =CHOOSE(F27+1,"Sunday","Monday","Tuesday","Wednesday","Thursday","Friday","Saturday") -> Sunday | Q27: =IF(OR(F27=0,F27=6),"Weekend","Weekday") -> Weekend | R27: =IF(D27<6,"Night",IF(D27<12,"Morning",IF(D27<17,"Afternoon",IF(D27<21,"Evening","Night")))) -> Night | S27: =INDEX(calculate_field!$F$2:$F$4, MATCH(H27, calculate_field!$E$2:$E$4, 1)) -> Warm | T27: =AVERAGE(N27:N50) -> 32.958333 | U27: =_xlfn.STDEV.S(N27:N50) -> 30.276234 | V27: =(N50-T50)/U50 -> -1.0957046 | W27: =IFERROR(ABS(V43)>1.5,FALSE) -> FALSE
A28: 27 | B28: 40545 | C28: 1 | D28: 2 | E28: FALSE | F28: 0 | G28: 2 | H28: 0.42 | I28: 0.4242 | J28: 1 | K28: 0.2836 | L28: 1 | M28: 8 | N28: 9 | O28: =VLOOKUP(G28,calculate_field!$B$2:$C$5,2,FALSE) -> Mist / cloudy | P28: =CHOOSE(F28+1,"Sunday","Monday","Tuesday","Wednesday","Thursday","Friday","Saturday") -> Sunday | Q28: =IF(OR(F28=0,F28=6),"Weekend","Weekday") -> Weekend | R28: =IF(D28<6,"Night",IF(D28<12,"Morning",IF(D28<17,"Afternoon",IF(D28<21,"Evening","Night")))) -> Night | S28: =INDEX(calculate_field!$F$2:$F$4, MATCH(H28, calculate_field!$E$2:$E$4, 1)) -> Warm | T28: =AVERAGE(N28:N51) -> 32.291667 | U28: =_xlfn.STDEV.S(N28:N51) -> 30.814281 | V28: =(N51-T51)/U51 -> -1.1158709 | W28: =IFERROR(ABS(V44)>1.5,FALSE) -> FALSE
A29: 28 | B29: 40545 | C29: 1 | D29: 3 | E29: FALSE | F29: 0 | G29: 2 | H29: 0.46 | I29: 0.4545 | J29: 0.94 | K29: 0.194 | L29: 2 | M29: 4 | N29: 6 | O29: =VLOOKUP(G29,calculate_field!$B$2:$C$5,2,FALSE) -> Mist / cloudy | P29: =CHOOSE(F29+1,"Sunday","Monday","Tuesday","Wednesday","Thursday","Friday","Saturday") -> Sunday | Q29: =IF(OR(F29=0,F29=6),"Weekend","Weekday") -> Weekend | R29: =IF(D29<6,"Night",IF(D29<12,"Morning",IF(D29<17,"Afternoon",IF(D29<21,"Evening","Night")))) -> Night | S29: =INDEX(calculate_field!$F$2:$F$4, MATCH(H29, calculate_field!$E$2:$E$4, 1)) -> Warm | T29: =AVERAGE(N29:N52) -> 32.041667 | U29: =_xlfn.STDEV.S(N29:N52) -> 31.035014 | V29: =(N52-T52)/U52 -> -1.0811544 | W29: =IFERROR(ABS(V45)>1.5,FALSE) -> FALSE
A30: 29 | B30: 40545 | C30: 1 | D30: 4 | E30: FALSE | F30: 0 | G30: 2 | H30: 0.46 | I30: =IF(I13="", _xlfn.MODE.SNGL($I$2:$I$1000), I13) -> 0.3333 | J30: 0.94 | K30: 0.194 | L30: 2 | M30: 1 | N30: 3 | O30: =VLOOKUP(G30,calculate_field!$B$2:$C$5,2,FALSE) -> Mist / cloudy | P30: =CHOOSE(F30+1,"Sunday","Monday","Tuesday","Wednesday","Thursday","Friday","Saturday") -> Sunday | Q30: =IF(OR(F30=0,F30=6),"Weekend","Weekday") -> Weekend | R30: =IF(D30<6,"Night",IF(D30<12,"Morning",IF(D30<17,"Afternoon",IF(D30<21,"Evening","Night")))) -> Night | S30: =INDEX(calculate_field!$F$2:$F$4, MATCH(H30, calculate_field!$E$2:$E$4, 1)) -> Warm | T30: =AVERAGE(N30:N53) -> 33.041667 | U30: =_xlfn.STDEV.S(N30:N53) -> 30.542172 | V30: =(N53-T53)/U53 -> -0.57577218 | W30: =IFERROR(ABS(V46)>1.5,FALSE) -> FALSE
A31: 30 | B31: 40545 | C31: 1 | D31: 6 | E31: FALSE | F31: 0 | G31: 3 | H31: 0.42 | I31: 0.4242 | J31: 0.77 | K31: 0.2985 | L31: 0 | M31: 2 | N31: 2 | O31: =VLOOKUP(G31,calculate_field!$B$2:$C$5,2,FALSE) -> Light Snow / Rain | P31: =CHOOSE(F31+1,"Sunday","Monday","Tuesday","Wednesday","Thursday","Friday","Saturday") -> Sunday | Q31: =IF(OR(F31=0,F31=6),"Weekend","Weekday") -> Weekend | R31: =IF(D31<6,"Night",IF(D31<12,"Morning",IF(D31<17,"Afternoon",IF(D31<21,"Evening","Night")))) -> Morning | S31: =INDEX(calculate_field!$F$2:$F$4, MATCH(H31, calculate_field!$E$2:$E$4, 1)) -> Warm | T31: =AVERAGE(N31:N54) -> 35.583333 | U31: =_xlfn.STDEV.S(N31:N54) -> 30.471536 | V31: =(N54-T54)/U54 -> 0.072159447 | W31: =IFERROR(ABS(V47)>1.5,FALSE) -> FALSE
A32: 31 | B32: 40545 | C32: 1 | D32: 7 | E32: FALSE | F32: 0 | G32: 2 | H32: 0.4 | I32: 0.4091 | J32: 0.76 | K32: 0.194 | L32: 0 | M32: 1 | N32: 1 | O32: =VLOOKUP(G32,calculate_field!$B$2:$C$5,2,FALSE) -> Mist / cloudy | P32: =CHOOSE(F32+1,"Sunday","Monday","Tuesday","Wednesday","Thursday","Friday","Saturday") -> Sunday | Q32: =IF(OR(F32=0,F32=6),"Weekend","Weekday") -> Weekend | R32: =IF(D32<6,"Night",IF(D32<12,"Morning",IF(D32<17,"Afternoon",IF(D32<21,"Evening","Night")))) -> Morning | S32: =INDEX(calculate_field!$F$2:$F$4, MATCH(H32, calculate_field!$E$2:$E$4, 1)) -> Warm | T32: =AVERAGE(N32:N55) -> 41.916667 | U32: =_xlfn.STDEV.S(N32:N55) -> 38.043358 | V32: =(N55-T55)/U55 -> 1.6364037 | W32: =IFERROR(ABS(V48)>1.5,FALSE) -> FALSE
A33: 32 | B33: 40545 | C33: 1 | D33: 8 | E33: FALSE | F33: 0 | G33: 3 | H33: 0.4 | I33: 0.4091 | J33: 0.71 | K33: 0.2239 | L33: 0 | M33: 8 | N33: 8 | O33: =VLOOKUP(G33,calculate_field!$B$2:$C$5,2,FALSE) -> Light Snow / Rain | P33: =CHOOSE(F33+1,"Sunday","Monday","Tuesday","Wednesday","Thursday","Friday","Saturday") -> Sunday | Q33: =IF(OR(F33=0,F33=6),"Weekend","Weekday") -> Weekend | R33: =IF(D33<6,"Night",IF(D33<12,"Morning",IF(D33<17,"Afternoon",IF(D33<21,"Evening","Night")))) -> Morning | S33: =INDEX(calculate_field!$F$2:$F$4, MATCH(H33, calculate_field!$E$2:$E$4, 1)) -> Warm | T33: =AVERAGE(N33:N56) -> 45.541667 | U33: =_xlfn.STDEV.S(N33:N56) -> 38.119924 | V33: =(N56-T56)/U56 -> 0.48541942 | W33: =IFERROR(ABS(V49)>1.5,FALSE) -> FALSE
A34: 33 | B34: 40545 | C34: 1 | D34: 9 | E34: FALSE | F34: 0 | G34: 2 | H34: 0.38 | I34: =IF(I17="", _xlfn.MODE.SNGL($I$2:$I$1000), I17) -> 0.4394 | J34: 0.76 | K34: 0.2239 | L34: 1 | M34: 19 | N34: 20 | O34: =VLOOKUP(G34,calculate_field!$B$2:$C$5,2,FALSE) -> Mist / cloudy | P34: =CHOOSE(F34+1,"Sunday","Monday","Tuesday","Wednesday","Thursday","Friday","Saturday") -> Sunday | Q34: =IF(OR(F34=0,F34=6),"Weekend","Weekday") -> Weekend | R34: =IF(D34<6,"Night",IF(D34<12,"Morning",IF(D34<17,"Afternoon",IF(D34<21,"Evening","Night")))) -> Morning | S34: =INDEX(calculate_field!$F$2:$F$4, MATCH(H34, calculate_field!$E$2:$E$4, 1)) -> Warm | T34: =AVERAGE(N34:N57) -> 47.041667 | U34: =_xlfn.STDEV.S(N34:N57) -> 37.277431 | V34: =(N57-T57)/U57 -> -0.33380479 | W34: =IFERROR(ABS(V50)>1.5,FALSE) -> FALSE
A35: 34 | B35: 40545 | C35: 1 | D35: 10 | E35: FALSE | F35: 0 | G35: 2 | H35: 0.36 | I35: 0.3485 | J35: 0.81 | K35: 0.2239 | L35: 7 | M35: 46 | N35: 53 | O35: =VLOOKUP(G35,calculate_field!$B$2:$C$5,2,FALSE) -> Mist / cloudy | P35: =CHOOSE(F35+1,"Sunday","Monday","Tuesday","Wednesday","Thursday","Friday","Saturday") -> Sunday | Q35: =IF(OR(F35=0,F35=6),"Weekend","Weekday") -> Weekend | R35: =IF(D35<6,"Night",IF(D35<12,"Morning",IF(D35<17,"Afternoon",IF(D35<21,"Evening","Night")))) -> Morning | S35: =INDEX(calculate_field!$F$2:$F$4, MATCH(H35, calculate_field!$E$2:$E$4, 1)) -> Warm | T35: =AVERAGE(N35:N58) -> 48.333333 | U35: =_xlfn.STDEV.S(N35:N58) -> 36.834137 | V35: =(N58-T58)/U58 -> -0.20840556 | W35: =IFERROR(ABS(V51)>1.5,FALSE) -> FALSE
A36: 35 | B36: 40545 | C36: 1 | D36: 11 | E36: FALSE | F36: 0 | G36: 2 | H36: 0.36 | I36: 0.3333 | J36: 0.71 | K36: 0.2537 | L36: 16 | M36: 54 | N36: 70 | O36: =VLOOKUP(G36,calculate_field!$B$2:$C$5,2,FALSE) -> Mist / cloudy | P36: =CHOOSE(F36+1,"Sunday","Monday","Tuesday","Wednesday","Thursday","Friday","Saturday") -> Sunday | Q36: =IF(OR(F36=0,F36=6),"Weekend","Weekday") -> Weekend | R36: =IF(D36<6,"Night",IF(D36<12,"Morning",IF(D36<17,"Afternoon",IF(D36<21,"Evening","Night")))) -> Morning | S36: =INDEX(calculate_field!$F$2:$F$4, MATCH(H36, calculate_field!$E$2:$E$4, 1)) -> Warm | T36: =AVERAGE(N36:N59) -> 48.666667 | U36: =_xlfn.STDEV.S(N36:N59) -> 36.914315 | V36: =(N59-T59)/U59 -> -0.034970054 | W36: =IFERROR(ABS(V52)>1.5,FALSE) -> FALSE
A37: 36 | B37: 40545 | C37: 1 | D37: 12 | E37: FALSE | F37: 0 | G37: 2 | H37: 0.36 | I37: 0.3333 | J37: 0.66 | K37: 0.2985 | L37: 20 | M37: 73 | N37: 93 | O37: =VLOOKUP(G37,calculate_field!$B$2:$C$5,2,FALSE) -> Mist / cloudy | P37: =CHOOSE(F37+1,"Sunday","Monday","Tuesday","Wednesday","Thursday","Friday","Saturday") -> Sunday | Q37: =IF(OR(F37=0,F37=6),"Weekend","Weekday") -> Weekend | R37: =IF(D37<6,"Night",IF(D37<12,"Morning",IF(D37<17,"Afternoon",IF(D37<21,"Evening","Night")))) -> Afternoon | S37: =INDEX(calculate_field!$F$2:$F$4, MATCH(H37, calculate_field!$E$2:$E$4, 1)) -> Warm | T37: =AVERAGE(N37:N60) -> 48.291667 | U37: =_xlfn.STDEV.S(N37:N60) -> 36.733445 | V37: =(N60-T60)/U60 -> -0.06366317 | W37: =IFERROR(ABS(V53)>1.5,FALSE) -> FALSE
A38: 37 | B38: 40545 | C38: 1 | D38: 13 | E38: FALSE | F38: 0 | G38: 2 | H38: 0.36 | I38: 0.3485 | J38: 0.66 | K38: 0.1343 | L38: 11 | M38: 64 | N38: 75 | O38: =VLOOKUP(G38,calculate_field!$B$2:$C$5,2,FALSE) -> Mist / cloudy | P38: =CHOOSE(F38+1,"Sunday","Monday","Tuesday","Wednesday","Thursday","Friday","Saturday") -> Sunday | Q38: =IF(OR(F38=0,F38=6),"Weekend","Weekday") -> Weekend | R38: =IF(D38<6,"Night",IF(D38<12,"Morning",IF(D38<17,"Afternoon",IF(D38<21,"Evening","Night")))) -> Afternoon | S38: =INDEX(calculate_field!$F$2:$F$4, MATCH(H38, calculate_field!$E$2:$E$4, 1)) -> Warm | T38: =AVERAGE(N38:N61) -> 47.625 | U38: =_xlfn.STDEV.S(N38:N61) -> 36.025127 | V38: =(N61-T61)/U61 -> 0.244195 | W38: =IFERROR(ABS(V54)>1.5,FALSE) -> FALSE
A39: 38 | B39: 40545 | C39: 1 | D39: 14 | E39: FALSE | F39: 0 | G39: 3 | H39: 0.36 | I39: =IF(I22="", _xlfn.MODE.SNGL($I$2:$I$1000), I22) -> 0.4091 | J39: 0.76 | K39: 0.194 | L39: 4 | M39: 55 | N39: 59 | O39: =VLOOKUP(G39,calculate_field!$B$2:$C$5,2,FALSE) -> Light Snow / Rain | P39: =CHOOSE(F39+1,"Sunday","Monday","Tuesday","Wednesday","Thursday","Friday","Saturday") -> Sunday | Q39: =IF(OR(F39=0,F39=6),"Weekend","Weekday") -> Weekend | R39: =IF(D39<6,"Night",IF(D39<12,"Morning",IF(D39<17,"Afternoon",IF(D39<21,"Evening","Night")))) -> Afternoon | S39: =INDEX(calculate_field!$F$2:$F$4, MATCH(H39, calculate_field!$E$2:$E$4, 1)) -> Warm | T39: =AVERAGE(N39:N62) -> 47.5 | U39: =_xlfn.STDEV.S(N39:N62) -> 35.931093 | V39: =(N62-T62)/U62 -> 0.15736652 | W39: =IFERROR(ABS(V55)>1.5,FALSE) -> TRUE
A40: 39 | B40: 40545 | C40: 1 | D40: 15 | E40: FALSE | F40: 0 | G40: 3 | H40: 0.34 | I40: 0.3333 | J40: 0.81 | K40: 0.1642 | L40: 19 | M40: 55 | N40: 74 | O40: =VLOOKUP(G40,calculate_field!$B$2:$C$5,2,FALSE) -> Light Snow / Rain | P40: =CHOOSE(F40+1,"Sunday","Monday","Tuesday","Wednesday","Thursday","Friday","Saturday") -> Sunday | Q40: =IF(OR(F40=0,F40=6),"Weekend","Weekday") -> Weekend | R40: =IF(D40<6,"Night",IF(D40<12,"Morning",IF(D40<17,"Afternoon",IF(D40<21,"Evening","Night")))) -> Afternoon | S40: =INDEX(calculate_field!$F$2:$F$4, MATCH(H40, calculate_field!$E$2:$E$4, 1)) -> Warm | T40: =AVERAGE(N40:N63) -> 48.208333 | U40: =_xlfn.STDEV.S(N40:N63) -> 36.332976 | V40: =(N63-T63)/U63 -> 0.22542107 | W40: =IFERROR(ABS(V56)>1.5,FALSE) -> FALSE
...

Sheet calculate_field
B1: weathersit | C1: weather_Category | E1: Min Temp °C | F1: Temp Category
B2: 1 | C2: Clear/Partly Cloudy | E2: 0 | F2: Cold
B3: 2 | C3: Mist / cloudy | E3: 0.2 | F3: Mild
B4: 3 | C4: Light Snow / Rain | E4: 0.3 | F4: Warm
B5: 4 | C5: Heavy Rain
B9: Formula | C9: Matric | D9: value
B10: Sum | C10: Total Rentals (cnt) | D10: =SUM('clean data'!N:N) -> 58304 | F10: Row Labels | G10: StdDev of cnt
B11: Avg | C11: Avg of cnt | D11: =AVERAGE('clean data'!N:N) -> 58.304 | F11: Clear/Partly Cloudy | G11: 52.059306
B12: Sum | C12: Total Rentals (casual) | D12: =SUM('clean data'!L:L) -> 4921 | F12: Heavy Rain | G12: #DIV/0!
B13: Sum | C13: Total Rentals (Registration) | D13: =SUM('clean data'!M:M) -> 53383 | F13: Light Snow / Rain | G13: 31.519655
F14: Mist / cloudy | G14: 51.424211
F15: Grand Total | G15: 50.985558
B16: countif | C16: total weekdays Record | D16: =COUNTIF('clean data'!Q:Q,"weekday") -> 670
B17: countif | C17: total weekends Record | D17: =COUNTIF('clean data'!Q:Q,'clean data'!Q2) -> 330
B18: countif | C18: total cold record | D18: =COUNTIF('clean data'!S:S,"cold") -> 425
B19: countif | C19: total warm record | D19: =COUNTIF('clean data'!S:S,"Warm") -> 138
B20: countif | C20: total Mild record | D20: =COUNTIF('clean data'!S:S,"Mild") -> 437
B22: sumif | C22: Total bike rentals on weekends | D22: =SUMIF('clean data'!Q:Q,"weekend",'clean data'!N:N) -> 15869
B23: sumif | C23: Total bike rentals on weekdays | D23: =SUMIF('clean data'!Q:Q,"weekday",'clean data'!N:N) -> 42435
B25: sumif | C25: Total rentals during Warm temperature | D25: =SUMIF('clean data'!S:S,"warm",'clean data'!N:N) -> 11820
B26: sumif | C26: Total rentals during mild temperature | D26: =SUMIF('clean data'!S:S,"mild",'clean data'!N:N) -> 26218
B27: sumif | C27: Total rentals during cold temperature | D27: =SUMIF('clean data'!S:S,"cold",'clean data'!N:N) -> 20266
B31: coreel | C31: Correlation(cnt,temp) | D31: =CORREL('clean data'!N:N,'clean data'!H:H) -> 0.22929155
B32: coreel | C32: Correlation(cnt,atemp) | D32: =CORREL('clean data'!N:N,'clean data'!I:I) -> 0.17935425
B33: coreel | C33: Correlation(cnt,hum) | D33: =CORREL('clean data'!N:N,'clean data'!J:J) -> -0.2543533
B34: coreel | C34: Correlation(cnt,windspeed) | D34: =CORREL('clean data'!N:N,'clean data'!K:K) -> 0.10399668

Sheet deshboard

Sheet weektype
D2: Weekday vs Weekend Bike Rental Usage
B9: Row Labels | C9: Sum of casual | D9: Sum of reg
B10: Weekday | C10: 2219 | D10: 40216
B11: Weekend | C11: 2702 | D11: 13167
B12: Grand Total | C12: 4921 | D12: 53383

Sheet Hrs wise count
C2: HRS WISE SUM OF REGISTRATION & CASUAL
B5: Row Labels | C5: Sum of registered | D5: Sum of casual
B6: 0 | C6: 629 | D6: 74
B7: 1 | C7: 412 | D7: 48
B8: 2 | C8: 261 | D8: 33
B9: 3 | C9: 117 | D9: 34
B10: 4 | C10: 62 | D10: 7
B11: 5 | C11: 161 | D11: 3
B12: 6 | C12: 801 | D12: 21
B13: 7 | C13: 2275 | D13: 64
B14: 8 | C14: 5261 | D14: 127
B15: 9 | C15: 3500 | D15: 172
B16: 10 | C16: 2037 | D16: 216
B17: 11 | C17: 2127 | D17: 367
... B29: 23 | C29: 982 | D29: 101
B30: Grand Total | C30: 53383 | D30: 4921

Sheet weth_cat wise users
C2: WEATHER CATEGORY WISE TOTAL CASUAL & REGISTRATION USERS
B12: Row Labels | C12: Sum of casual | D12: Sum of registered
B13: Clear/Partly Cloudy | C13: 3211 | D13: 34162
B14: Heavy Rain | C14: 1 | D14: 35
B15: Light Snow / Rain | C15: 171 | D15: 2618
B16: Mist / cloudy | C16: 1538 | D16: 16568
B17: Grand Total | C17: 4921 | D17: 53383

Sheet monwise count
C2: MONTH WISE TOTAL COUNT
B9: Row Labels | C9: Sum of cnt
B10: Jan | C10: 38189
B11: Feb | C11: 20115
B12: Grand Total | C12: 58304

Sheet weth_cat Avg
C2: WEATHER CATEGORY WISE AVERAGE OF COUNT
B10: Row Labels | C10: Average of cnt
B11: Clear/Partly Cloudy | C11: 61.671617
B12: Heavy Rain | C12: 36
B13: Light Snow / Rain | C13: 33.202381
B14: Mist / cloudy | C14: 58.595469
B15: Grand Total | C15: 58.304

Sheet Temp_catg
C3: TEMPURATURE CATEGORIES WISE SUM OF CASUAL AND REGESTRATION
B12: Row Labels | C12: Sum of casual | D12: Sum of registered
B13: Sunday | C13: 1477 | D13: 6644
B14: Monday | C14: 534 | D14: 7916
B15: Tuesday | C15: 457 | D15: 7926
B16: Wednesday | C16: 344 | D16: 7705
B17: Thursday | C17: 332 | D17: 8126
B18: Friday | C18: 552 | D18: 8543
B19: Saturday | C19: 1225 | D19: 6523
B20: Grand Total | C20: 4921 | D20: 53383

Sheet funnel of users
D7: TOTAL STAGES BY VALUE
C13: A | D13: B
C14: Stage | D14: Value
C15: Total Users | D15: 58304
C16: Registered Users | D16: 53383
C17: Casual Users | D17: 4931

Sheet Temp_cat sum of casu & reg
D2: TEMPURATURE CATEGORIES WISE SUM OF CASUAL AND REGESTRATION
B9: Temp_cat | C9: Sum of casual | D9: Sum of registered
B10: Cold | C10: 970 | D10: 19296
B11: Mild | C11: 1984 | D11: 24234
B12: Warm | C12: 1967 | D12: 9853
B13: Grand Total | C13: 4921 | D13: 53383

Sheet time_prd combo
C2: TIME PERIOD WISE SUM OF CAUSALS & REG
B10: Row Labels | C10: Sum of casual | D10: Sum of reg
B11: Afternoon | C11: 2490 | D11: 14649
B12: Evening | C12: 944 | D12: 16825
B13: Morning | C13: 967 | D13: 16001
B14: Night | C14: 520 | D14: 5908

Sheet Heatmap
B2: hrs | C2: sum_cnt | K2: SUMMARY & INSIGHTS
B3: Hrs | C3: Sun | D3: Mon | E3: Tue | F3: Wed | G3: Thur | H3: Fri | I3: Sat
B4: 0 | C4: 214 | D4: 67 | E4: 44 | F4: 52 | G4: 59 | H4: 88 | I4: 179 | K4: I created an hour-by-weekday heatmap using SUM(cnt) with conditional formatting to highlight peak and off-peak demand,where green represents low demand, yellow indicates medium demand, and red highlights high demand. enabling clear comparison between weekday and weekend usage patterns.The heatmap excludes grand totals to maintain accurate color scaling and highlight true demand patterns
B5: 1 | C5: 162 | D5: 39 | E5: 17 | F5: 34 | G5: 23 | H5: 35 | I5: 150
B6: 2 | C6: 105 | D6: 17 | E6: 10 | F6: 23 | G6: 11 | H6: 10 | I6: 118
B7: 3 | C7: 63 | D7: 9 | E7: 3 | F7: 3 | G7: 5 | H7: 4 | I7: 64
B8: 4 | C8: 10 | D8: 14 | E8: 6 | F8: 5 | G8: 7 | H8: 2 | I8: 25
B9: 5 | C9: 10 | D9: 33 | E9: 24 | F9: 26 | G9: 21 | H9: 33 | I9: 17
B10: 6 | C10: 11 | D10: 174 | E10: 160 | F10: 150 | G10: 164 | H10: 146 | I10: 17
B11: 7 | C11: 26 | D11: 503 | E11: 453 | F11: 410 | G11: 454 | H11: 443 | I11: 50
B12: 8 | C12: 102 | D12: 967 | E12: 1012 | F12: 946 | G12: 1036 | H12: 1178 | I12: 147 | K12: 1. Peak demand occurs during commuting hours (8–9 AM and 5–7 PM) across weekdays, showing clear work-travel patterns
B13: 9 | C13: 229 | D13: 561 | E13: 625 | F13: 609 | G13: 659 | H13: 785 | I13: 204
B14: 10 | C14: 497 | D14: 296 | E14: 246 | F14: 291 | G14: 227 | H14: 314 | I14: 382
B15: 11 | C15: 599 | D15: 286 | E15: 254 | F15: 267 | G15: 273 | H15: 337 | I15: 478
B16: 12 | C16: 819 | D16: 390 | E16: 364 | F16: 377 | G16: 358 | H16: 384 | I16: 591 | K16: 2. Friday is the busiest day, recording the highest demand in both morning and evening peak periods.
B17: 13 | C17: 775 | D17: 386 | E17: 366 | F17: 389 | G17: 361 | H17: 446 | I17: 653
B18: 14 | C18: 776 | D18: 401 | E18: 340 | F18: 338 | G18: 288 | H18: 389 | I18: 668
B19: 15 | C19: 799 | D19: 361 | E19: 334 | F19: 376 | G19: 302 | H19: 410 | I19: 770
B20: 16 | C20: 746 | D20: 502 | E20: 483 | F20: 479 | G20: 437 | H20: 578 | I20: 703 | K20: 3. Early morning hours (2–5 AM) show the lowest usage, identifying consistent off-peak periods.
B21: 17 | C21: 610 | D21: 967 | E21: 1047 | F21: 908 | G21: 973 | H21: 1072 | I21: 592
B22: 18 | C22: 455 | D22: 888 | E22: 955 | F22: 819 | G22: 903 | H22: 820 | I22: 443
B23: 19 | C23: 319 | D23: 610 | E23: 617 | F23: 506 | G23: 650 | H23: 576 | I23: 383
B24: 20 | C24: 258 | D24: 406 | E24: 418 | F24: 380 | G24: 524 | H24: 368 | I24: 302 | K24: 4. Weekday demand is higher and more structured than weekends, while weekend usage is more evenly spread throughout the day
B25: 21 | C25: 210 | D25: 310 | E25: 272 | F25: 305 | G25: 309 | H25: 280 | I25: 310
B26: 22 | C26: 192 | D26: 163 | E26: 215 | F26: 220 | G26: 257 | H26: 221 | I26: 240
B27: 23 | C27: 134 | D27: 100 | E27: 118 | F27: 136 | G27: 157 | H27: 176 | I27: 262
